[2022-02-01 12:16:26,067] {taskinstance.py:1032} INFO - Dependencies all met for <TaskInstance: data_ingestion_fhv_dag.download_data_task scheduled__2019-02-01T00:00:00+00:00 [queued]>
[2022-02-01 12:16:26,080] {taskinstance.py:1032} INFO - Dependencies all met for <TaskInstance: data_ingestion_fhv_dag.download_data_task scheduled__2019-02-01T00:00:00+00:00 [queued]>
[2022-02-01 12:16:26,081] {taskinstance.py:1238} INFO - 
--------------------------------------------------------------------------------
[2022-02-01 12:16:26,081] {taskinstance.py:1239} INFO - Starting attempt 1 of 1
[2022-02-01 12:16:26,082] {taskinstance.py:1240} INFO - 
--------------------------------------------------------------------------------
[2022-02-01 12:16:26,153] {taskinstance.py:1259} INFO - Executing <Task(BashOperator): download_data_task> on 2019-02-01 00:00:00+00:00
[2022-02-01 12:16:26,157] {standard_task_runner.py:52} INFO - Started process 2706 to run task
[2022-02-01 12:16:26,161] {standard_task_runner.py:76} INFO - Running: ['***', 'tasks', 'run', 'data_ingestion_fhv_dag', 'download_data_task', 'scheduled__2019-02-01T00:00:00+00:00', '--job-id', '5', '--raw', '--subdir', 'DAGS_FOLDER/data_ingestion_fhv_dag.py', '--cfg-path', '/tmp/tmp3y2yiudp', '--error-file', '/tmp/tmpd1h9w2in']
[2022-02-01 12:16:26,163] {standard_task_runner.py:77} INFO - Job 5: Subtask download_data_task
[2022-02-01 12:16:26,257] {logging_mixin.py:109} INFO - Running <TaskInstance: data_ingestion_fhv_dag.download_data_task scheduled__2019-02-01T00:00:00+00:00 [running]> on host 153a4cabbd26
[2022-02-01 12:16:26,362] {logging_mixin.py:109} WARNING - /home/***/.local/lib/python3.7/site-packages/***/utils/context.py:152 AirflowContextDeprecationWarning: Accessing 'execution_date' from the template is deprecated and will be removed in a future version. Please use 'data_interval_start' or 'logical_date' instead.
[2022-02-01 12:16:26,418] {taskinstance.py:1426} INFO - Exporting the following env vars:
AIRFLOW_CTX_DAG_OWNER=***
AIRFLOW_CTX_DAG_ID=data_ingestion_fhv_dag
AIRFLOW_CTX_TASK_ID=download_data_task
AIRFLOW_CTX_EXECUTION_DATE=2019-02-01T00:00:00+00:00
AIRFLOW_CTX_DAG_RUN_ID=scheduled__2019-02-01T00:00:00+00:00
[2022-02-01 12:16:26,420] {subprocess.py:62} INFO - Tmp dir root location: 
 /tmp
[2022-02-01 12:16:26,421] {subprocess.py:74} INFO - Running command: ['bash', '-c', 'curl -sSL https://nyc-tlc.s3.amazonaws.com/trip+data/fhv_tripdata_2019-02.csv > /opt/***/fhv_tripdata_2019-02.csv']
[2022-02-01 12:16:26,434] {subprocess.py:85} INFO - Output:
[2022-02-01 12:51:15,395] {local_task_job.py:212} WARNING - State of this instance has been externally set to failed. Terminating instance.
[2022-02-01 12:51:15,426] {process_utils.py:124} INFO - Sending Signals.SIGTERM to group 2706. PIDs of all processes in the group: [2707, 2708, 2706]
[2022-02-01 12:51:15,429] {process_utils.py:75} INFO - Sending the signal Signals.SIGTERM to group 2706
[2022-02-01 12:51:15,442] {taskinstance.py:1408} ERROR - Received SIGTERM. Terminating subprocesses.
[2022-02-01 12:51:15,453] {subprocess.py:99} INFO - Sending SIGTERM signal to process group
[2022-02-01 12:51:15,771] {process_utils.py:70} INFO - Process psutil.Process(pid=2708, status='terminated', started='12:16:25') (2708) terminated with exit code None
[2022-02-01 12:51:16,067] {process_utils.py:70} INFO - Process psutil.Process(pid=2706, status='terminated', exitcode=0, started='12:16:25') (2706) terminated with exit code 0
[2022-02-01 12:51:16,069] {process_utils.py:70} INFO - Process psutil.Process(pid=2707, status='terminated', started='12:16:25') (2707) terminated with exit code None
[2022-02-01 12:52:38,263] {taskinstance.py:1032} INFO - Dependencies all met for <TaskInstance: data_ingestion_fhv_dag.download_data_task scheduled__2019-02-01T00:00:00+00:00 [queued]>
[2022-02-01 12:52:38,312] {taskinstance.py:1032} INFO - Dependencies all met for <TaskInstance: data_ingestion_fhv_dag.download_data_task scheduled__2019-02-01T00:00:00+00:00 [queued]>
[2022-02-01 12:52:38,313] {taskinstance.py:1238} INFO - 
--------------------------------------------------------------------------------
[2022-02-01 12:52:38,314] {taskinstance.py:1239} INFO - Starting attempt 1 of 1
[2022-02-01 12:52:38,314] {taskinstance.py:1240} INFO - 
--------------------------------------------------------------------------------
[2022-02-01 12:52:38,391] {taskinstance.py:1259} INFO - Executing <Task(BashOperator): download_data_task> on 2019-02-01 00:00:00+00:00
[2022-02-01 12:52:38,401] {standard_task_runner.py:52} INFO - Started process 7020 to run task
[2022-02-01 12:52:38,408] {standard_task_runner.py:76} INFO - Running: ['***', 'tasks', 'run', 'data_ingestion_fhv_dag', 'download_data_task', 'scheduled__2019-02-01T00:00:00+00:00', '--job-id', '8', '--raw', '--subdir', 'DAGS_FOLDER/data_ingestion_fhv_dag.py', '--cfg-path', '/tmp/tmpnrlj9sjp', '--error-file', '/tmp/tmpes09fhxt']
[2022-02-01 12:52:38,411] {standard_task_runner.py:77} INFO - Job 8: Subtask download_data_task
[2022-02-01 12:52:38,661] {logging_mixin.py:109} INFO - Running <TaskInstance: data_ingestion_fhv_dag.download_data_task scheduled__2019-02-01T00:00:00+00:00 [running]> on host 153a4cabbd26
[2022-02-01 12:52:38,791] {logging_mixin.py:109} WARNING - /home/***/.local/lib/python3.7/site-packages/***/utils/context.py:152 AirflowContextDeprecationWarning: Accessing 'execution_date' from the template is deprecated and will be removed in a future version. Please use 'data_interval_start' or 'logical_date' instead.
[2022-02-01 12:52:38,865] {taskinstance.py:1426} INFO - Exporting the following env vars:
AIRFLOW_CTX_DAG_OWNER=***
AIRFLOW_CTX_DAG_ID=data_ingestion_fhv_dag
AIRFLOW_CTX_TASK_ID=download_data_task
AIRFLOW_CTX_EXECUTION_DATE=2019-02-01T00:00:00+00:00
AIRFLOW_CTX_DAG_RUN_ID=scheduled__2019-02-01T00:00:00+00:00
[2022-02-01 12:52:38,867] {subprocess.py:62} INFO - Tmp dir root location: 
 /tmp
[2022-02-01 12:52:38,869] {subprocess.py:74} INFO - Running command: ['bash', '-c', 'curl -sSL https://nyc-tlc.s3.amazonaws.com/trip+data/fhv_tripdata_2019-02.csv > /opt/***/fhv_tripdata_2019-02.csv']
[2022-02-01 12:52:38,878] {subprocess.py:85} INFO - Output:
[2022-02-01 12:57:39,104] {subprocess.py:89} INFO - curl: (18) transfer closed with 82269122 bytes remaining to read
[2022-02-01 12:57:39,841] {subprocess.py:93} INFO - Command exited with return code 18
[2022-02-01 12:57:39,864] {taskinstance.py:1700} ERROR - Task failed with exception
Traceback (most recent call last):
  File "/home/airflow/.local/lib/python3.7/site-packages/airflow/models/taskinstance.py", line 1329, in _run_raw_task
    self._execute_task_with_callbacks(context)
  File "/home/airflow/.local/lib/python3.7/site-packages/airflow/models/taskinstance.py", line 1455, in _execute_task_with_callbacks
    result = self._execute_task(context, self.task)
  File "/home/airflow/.local/lib/python3.7/site-packages/airflow/models/taskinstance.py", line 1511, in _execute_task
    result = execute_callable(context=context)
  File "/home/airflow/.local/lib/python3.7/site-packages/airflow/operators/bash.py", line 188, in execute
    f'Bash command failed. The command returned a non-zero exit code {result.exit_code}.'
airflow.exceptions.AirflowException: Bash command failed. The command returned a non-zero exit code 18.
[2022-02-01 12:57:39,875] {taskinstance.py:1277} INFO - Marking task as FAILED. dag_id=data_ingestion_fhv_dag, task_id=download_data_task, execution_date=20190201T000000, start_date=20220201T125238, end_date=20220201T125739
[2022-02-01 12:58:22,036] {standard_task_runner.py:92} ERROR - Failed to execute job 8 for task download_data_task
Traceback (most recent call last):
  File "/home/airflow/.local/lib/python3.7/site-packages/airflow/task/task_runner/standard_task_runner.py", line 85, in _start_by_fork
    args.func(args, dag=self.dag)
  File "/home/airflow/.local/lib/python3.7/site-packages/airflow/cli/cli_parser.py", line 48, in command
    return func(*args, **kwargs)
  File "/home/airflow/.local/lib/python3.7/site-packages/airflow/utils/cli.py", line 92, in wrapper
    return f(*args, **kwargs)
  File "/home/airflow/.local/lib/python3.7/site-packages/airflow/cli/commands/task_command.py", line 298, in task_run
    _run_task_by_selected_method(args, dag, ti)
  File "/home/airflow/.local/lib/python3.7/site-packages/airflow/cli/commands/task_command.py", line 107, in _run_task_by_selected_method
    _run_raw_task(args, ti)
  File "/home/airflow/.local/lib/python3.7/site-packages/airflow/cli/commands/task_command.py", line 184, in _run_raw_task
    error_file=args.error_file,
  File "/home/airflow/.local/lib/python3.7/site-packages/airflow/utils/session.py", line 70, in wrapper
    return func(*args, session=session, **kwargs)
  File "/home/airflow/.local/lib/python3.7/site-packages/airflow/models/taskinstance.py", line 1329, in _run_raw_task
    self._execute_task_with_callbacks(context)
  File "/home/airflow/.local/lib/python3.7/site-packages/airflow/models/taskinstance.py", line 1455, in _execute_task_with_callbacks
    result = self._execute_task(context, self.task)
  File "/home/airflow/.local/lib/python3.7/site-packages/airflow/models/taskinstance.py", line 1511, in _execute_task
    result = execute_callable(context=context)
  File "/home/airflow/.local/lib/python3.7/site-packages/airflow/operators/bash.py", line 188, in execute
    f'Bash command failed. The command returned a non-zero exit code {result.exit_code}.'
airflow.exceptions.AirflowException: Bash command failed. The command returned a non-zero exit code 18.
[2022-02-01 12:58:22,056] {local_task_job.py:154} INFO - Task exited with return code 1
[2022-02-01 12:58:23,117] {local_task_job.py:264} INFO - 0 downstream tasks scheduled from follow-on schedule check
[2022-02-01 13:01:02,334] {taskinstance.py:1032} INFO - Dependencies all met for <TaskInstance: data_ingestion_fhv_dag.download_data_task scheduled__2019-02-01T00:00:00+00:00 [queued]>
[2022-02-01 13:01:02,345] {taskinstance.py:1032} INFO - Dependencies all met for <TaskInstance: data_ingestion_fhv_dag.download_data_task scheduled__2019-02-01T00:00:00+00:00 [queued]>
[2022-02-01 13:01:02,345] {taskinstance.py:1238} INFO - 
--------------------------------------------------------------------------------
[2022-02-01 13:01:02,346] {taskinstance.py:1239} INFO - Starting attempt 1 of 1
[2022-02-01 13:01:02,346] {taskinstance.py:1240} INFO - 
--------------------------------------------------------------------------------
[2022-02-01 13:01:02,539] {taskinstance.py:1259} INFO - Executing <Task(BashOperator): download_data_task> on 2019-02-01 00:00:00+00:00
[2022-02-01 13:01:02,544] {standard_task_runner.py:52} INFO - Started process 7932 to run task
[2022-02-01 13:01:02,549] {standard_task_runner.py:76} INFO - Running: ['***', 'tasks', 'run', 'data_ingestion_fhv_dag', 'download_data_task', 'scheduled__2019-02-01T00:00:00+00:00', '--job-id', '12', '--raw', '--subdir', 'DAGS_FOLDER/data_ingestion_fhv_dag.py', '--cfg-path', '/tmp/tmpl9lt4ce7', '--error-file', '/tmp/tmpbt9bdsf8']
[2022-02-01 13:01:02,550] {standard_task_runner.py:77} INFO - Job 12: Subtask download_data_task
[2022-02-01 13:01:02,709] {logging_mixin.py:109} INFO - Running <TaskInstance: data_ingestion_fhv_dag.download_data_task scheduled__2019-02-01T00:00:00+00:00 [running]> on host 153a4cabbd26
[2022-02-01 13:01:02,830] {logging_mixin.py:109} WARNING - /home/***/.local/lib/python3.7/site-packages/***/utils/context.py:152 AirflowContextDeprecationWarning: Accessing 'execution_date' from the template is deprecated and will be removed in a future version. Please use 'data_interval_start' or 'logical_date' instead.
[2022-02-01 13:01:02,892] {taskinstance.py:1426} INFO - Exporting the following env vars:
AIRFLOW_CTX_DAG_OWNER=***
AIRFLOW_CTX_DAG_ID=data_ingestion_fhv_dag
AIRFLOW_CTX_TASK_ID=download_data_task
AIRFLOW_CTX_EXECUTION_DATE=2019-02-01T00:00:00+00:00
AIRFLOW_CTX_DAG_RUN_ID=scheduled__2019-02-01T00:00:00+00:00
[2022-02-01 13:01:02,894] {subprocess.py:62} INFO - Tmp dir root location: 
 /tmp
[2022-02-01 13:01:02,895] {subprocess.py:74} INFO - Running command: ['bash', '-c', 'curl -sSL https://nyc-tlc.s3.amazonaws.com/trip+data/fhv_tripdata_2019-02.csv > /opt/***/fhv_tripdata_2019-02.csv']
[2022-02-01 13:01:02,904] {subprocess.py:85} INFO - Output:
[2022-02-01 13:04:19,207] {subprocess.py:93} INFO - Command exited with return code 0
[2022-02-01 13:04:19,300] {taskinstance.py:1277} INFO - Marking task as SUCCESS. dag_id=data_ingestion_fhv_dag, task_id=download_data_task, execution_date=20190201T000000, start_date=20220201T130102, end_date=20220201T130419
[2022-02-01 13:04:19,393] {local_task_job.py:154} INFO - Task exited with return code 0
[2022-02-01 13:04:19,544] {local_task_job.py:264} INFO - 1 downstream tasks scheduled from follow-on schedule check
