[2022-02-01 14:46:38,521] {taskinstance.py:1032} INFO - Dependencies all met for <TaskInstance: data_ingestion_gcs_dag.download_dataset_task scheduled__2019-03-01T00:00:00+00:00 [queued]>
[2022-02-01 14:46:38,537] {taskinstance.py:1032} INFO - Dependencies all met for <TaskInstance: data_ingestion_gcs_dag.download_dataset_task scheduled__2019-03-01T00:00:00+00:00 [queued]>
[2022-02-01 14:46:38,538] {taskinstance.py:1238} INFO - 
--------------------------------------------------------------------------------
[2022-02-01 14:46:38,538] {taskinstance.py:1239} INFO - Starting attempt 2 of 3
[2022-02-01 14:46:38,539] {taskinstance.py:1240} INFO - 
--------------------------------------------------------------------------------
[2022-02-01 14:46:38,626] {taskinstance.py:1259} INFO - Executing <Task(BashOperator): download_dataset_task> on 2019-03-01 00:00:00+00:00
[2022-02-01 14:46:38,631] {standard_task_runner.py:52} INFO - Started process 21060 to run task
[2022-02-01 14:46:38,635] {standard_task_runner.py:76} INFO - Running: ['***', 'tasks', 'run', 'data_ingestion_gcs_dag', 'download_dataset_task', 'scheduled__2019-03-01T00:00:00+00:00', '--job-id', '61', '--raw', '--subdir', 'DAGS_FOLDER/data_ingestion_gcs_dag.py', '--cfg-path', '/tmp/tmpysx9fq2k', '--error-file', '/tmp/tmpsh_qmgtk']
[2022-02-01 14:46:38,637] {standard_task_runner.py:77} INFO - Job 61: Subtask download_dataset_task
[2022-02-01 14:46:38,740] {logging_mixin.py:109} INFO - Running <TaskInstance: data_ingestion_gcs_dag.download_dataset_task scheduled__2019-03-01T00:00:00+00:00 [running]> on host 153a4cabbd26
[2022-02-01 14:46:39,018] {taskinstance.py:1426} INFO - Exporting the following env vars:
AIRFLOW_CTX_DAG_OWNER=***
AIRFLOW_CTX_DAG_ID=data_ingestion_gcs_dag
AIRFLOW_CTX_TASK_ID=download_dataset_task
AIRFLOW_CTX_EXECUTION_DATE=2019-03-01T00:00:00+00:00
AIRFLOW_CTX_DAG_RUN_ID=scheduled__2019-03-01T00:00:00+00:00
[2022-02-01 14:46:39,020] {subprocess.py:62} INFO - Tmp dir root location: 
 /tmp
[2022-02-01 14:46:39,021] {subprocess.py:74} INFO - Running command: ['bash', '-c', 'curl -sS https://s3.amazonaws.com/nyc-tlc/trip+data/yellow_tripdata_2019-03.csv > /opt/***/yellow_tripdata_2019-03.csv']
[2022-02-01 14:46:39,063] {subprocess.py:85} INFO - Output:
[2022-02-01 14:46:54,093] {local_task_job.py:212} WARNING - State of this instance has been externally set to restarting. Terminating instance.
[2022-02-01 14:46:54,098] {process_utils.py:124} INFO - Sending Signals.SIGTERM to group 21060. PIDs of all processes in the group: [21061, 21062, 21060]
[2022-02-01 14:46:54,099] {process_utils.py:75} INFO - Sending the signal Signals.SIGTERM to group 21060
[2022-02-01 14:46:54,099] {taskinstance.py:1408} ERROR - Received SIGTERM. Terminating subprocesses.
[2022-02-01 14:46:54,100] {subprocess.py:99} INFO - Sending SIGTERM signal to process group
[2022-02-01 14:46:54,114] {taskinstance.py:1700} ERROR - Task failed with exception
Traceback (most recent call last):
  File "/home/airflow/.local/lib/python3.7/site-packages/airflow/models/taskinstance.py", line 1329, in _run_raw_task
    self._execute_task_with_callbacks(context)
  File "/home/airflow/.local/lib/python3.7/site-packages/airflow/models/taskinstance.py", line 1455, in _execute_task_with_callbacks
    result = self._execute_task(context, self.task)
  File "/home/airflow/.local/lib/python3.7/site-packages/airflow/models/taskinstance.py", line 1511, in _execute_task
    result = execute_callable(context=context)
  File "/home/airflow/.local/lib/python3.7/site-packages/airflow/operators/bash.py", line 182, in execute
    cwd=self.cwd,
  File "/home/airflow/.local/lib/python3.7/site-packages/airflow/hooks/subprocess.py", line 87, in run_command
    for raw_line in iter(self.sub_process.stdout.readline, b''):
  File "/home/airflow/.local/lib/python3.7/site-packages/airflow/models/taskinstance.py", line 1410, in signal_handler
    raise AirflowException("Task received SIGTERM signal")
airflow.exceptions.AirflowException: Task received SIGTERM signal
[2022-02-01 14:46:54,214] {taskinstance.py:1277} INFO - Marking task as UP_FOR_RETRY. dag_id=data_ingestion_gcs_dag, task_id=download_dataset_task, execution_date=20190301T000000, start_date=20220201T144638, end_date=20220201T144654
[2022-02-01 14:46:54,305] {standard_task_runner.py:92} ERROR - Failed to execute job 61 for task download_dataset_task
Traceback (most recent call last):
  File "/home/airflow/.local/lib/python3.7/site-packages/airflow/task/task_runner/standard_task_runner.py", line 85, in _start_by_fork
    args.func(args, dag=self.dag)
  File "/home/airflow/.local/lib/python3.7/site-packages/airflow/cli/cli_parser.py", line 48, in command
    return func(*args, **kwargs)
  File "/home/airflow/.local/lib/python3.7/site-packages/airflow/utils/cli.py", line 92, in wrapper
    return f(*args, **kwargs)
  File "/home/airflow/.local/lib/python3.7/site-packages/airflow/cli/commands/task_command.py", line 298, in task_run
    _run_task_by_selected_method(args, dag, ti)
  File "/home/airflow/.local/lib/python3.7/site-packages/airflow/cli/commands/task_command.py", line 107, in _run_task_by_selected_method
    _run_raw_task(args, ti)
  File "/home/airflow/.local/lib/python3.7/site-packages/airflow/cli/commands/task_command.py", line 184, in _run_raw_task
    error_file=args.error_file,
  File "/home/airflow/.local/lib/python3.7/site-packages/airflow/utils/session.py", line 70, in wrapper
    return func(*args, session=session, **kwargs)
  File "/home/airflow/.local/lib/python3.7/site-packages/airflow/models/taskinstance.py", line 1329, in _run_raw_task
    self._execute_task_with_callbacks(context)
  File "/home/airflow/.local/lib/python3.7/site-packages/airflow/models/taskinstance.py", line 1455, in _execute_task_with_callbacks
    result = self._execute_task(context, self.task)
  File "/home/airflow/.local/lib/python3.7/site-packages/airflow/models/taskinstance.py", line 1511, in _execute_task
    result = execute_callable(context=context)
  File "/home/airflow/.local/lib/python3.7/site-packages/airflow/operators/bash.py", line 182, in execute
    cwd=self.cwd,
  File "/home/airflow/.local/lib/python3.7/site-packages/airflow/hooks/subprocess.py", line 87, in run_command
    for raw_line in iter(self.sub_process.stdout.readline, b''):
  File "/home/airflow/.local/lib/python3.7/site-packages/airflow/models/taskinstance.py", line 1410, in signal_handler
    raise AirflowException("Task received SIGTERM signal")
airflow.exceptions.AirflowException: Task received SIGTERM signal
[2022-02-01 14:46:54,441] {process_utils.py:70} INFO - Process psutil.Process(pid=21060, status='terminated', exitcode=1, started='14:46:37') (21060) terminated with exit code 1
[2022-02-01 14:46:54,442] {process_utils.py:70} INFO - Process psutil.Process(pid=21062, status='terminated', started='14:46:38') (21062) terminated with exit code None
[2022-02-01 14:46:54,443] {process_utils.py:70} INFO - Process psutil.Process(pid=21061, status='terminated', started='14:46:38') (21061) terminated with exit code None
